2024-07-15 01:52:47,991 INFO    StreamThr :63702 [internal.py:wandb_internal():85] W&B internal server running at pid: 63702, started at: 2024-07-15 01:52:47.990718
2024-07-15 01:52:47,992 DEBUG   HandlerThread:63702 [handler.py:handle_request():158] handle_request: status
2024-07-15 01:52:48,001 INFO    WriterThread:63702 [datastore.py:open_for_write():87] open: /Users/weichaozhou/Workspace/MIT-REALM/ada_cbf/f1tenth_gym/examples/wandb/run-20240715_015247-xo787mlp/run-xo787mlp.wandb
2024-07-15 01:52:48,002 DEBUG   SenderThread:63702 [sender.py:send():379] send: header
2024-07-15 01:52:48,021 DEBUG   SenderThread:63702 [sender.py:send():379] send: run
2024-07-15 01:52:48,232 ERROR   SenderThread:63702 [internal_api.py:execute():349] 404 response executing GraphQL.
2024-07-15 01:52:48,232 ERROR   SenderThread:63702 [internal_api.py:execute():350] {"errors":[{"message":"run \"xo787mlp\" not found while updating run","path":["upsertBucket"]}],"data":{"upsertBucket":null}}
2024-07-15 01:52:48,233 ERROR   SenderThread:63702 [sender.py:send_run():1009] It appears that you do not have permission to access the requested resource. Please reach out to the project owner to grant you access. If you have the correct permissions, verify that there are no issues with your networking setup.(Error 404: Not Found)
Traceback (most recent call last):
  File "/Users/weichaozhou/.pyenv/versions/3.10.6/lib/python3.10/site-packages/wandb/sdk/lib/retry.py", line 131, in __call__
    result = self._call_fn(*args, **kwargs)
  File "/Users/weichaozhou/.pyenv/versions/3.10.6/lib/python3.10/site-packages/wandb/sdk/internal/internal_api.py", line 345, in execute
    return self.client.execute(*args, **kwargs)  # type: ignore
  File "/Users/weichaozhou/.pyenv/versions/3.10.6/lib/python3.10/site-packages/wandb/vendor/gql-0.2.0/wandb_gql/client.py", line 52, in execute
    result = self._get_result(document, *args, **kwargs)
  File "/Users/weichaozhou/.pyenv/versions/3.10.6/lib/python3.10/site-packages/wandb/vendor/gql-0.2.0/wandb_gql/client.py", line 60, in _get_result
    return self.transport.execute(document, *args, **kwargs)
  File "/Users/weichaozhou/.pyenv/versions/3.10.6/lib/python3.10/site-packages/wandb/sdk/lib/gql_request.py", line 59, in execute
    request.raise_for_status()
  File "/Users/weichaozhou/.pyenv/versions/3.10.6/lib/python3.10/site-packages/requests/models.py", line 1021, in raise_for_status
    raise HTTPError(http_error_msg, response=self)
requests.exceptions.HTTPError: 404 Client Error: Not Found for url: https://api.wandb.ai/graphql

During handling of the above exception, another exception occurred:

Traceback (most recent call last):
  File "/Users/weichaozhou/.pyenv/versions/3.10.6/lib/python3.10/site-packages/wandb/sdk/internal/sender.py", line 1007, in send_run
    server_run = self._init_run(run, config_value_dict)
  File "/Users/weichaozhou/.pyenv/versions/3.10.6/lib/python3.10/site-packages/wandb/sdk/internal/sender.py", line 1079, in _init_run
    server_run, inserted, server_messages = self._api.upsert_run(
  File "/Users/weichaozhou/.pyenv/versions/3.10.6/lib/python3.10/site-packages/wandb/apis/normalize.py", line 73, in wrapper
    raise err
  File "/Users/weichaozhou/.pyenv/versions/3.10.6/lib/python3.10/site-packages/wandb/apis/normalize.py", line 41, in wrapper
    return func(*args, **kwargs)
  File "/Users/weichaozhou/.pyenv/versions/3.10.6/lib/python3.10/site-packages/wandb/sdk/internal/internal_api.py", line 2224, in upsert_run
    response = self.gql(
  File "/Users/weichaozhou/.pyenv/versions/3.10.6/lib/python3.10/site-packages/wandb/sdk/internal/internal_api.py", line 317, in gql
    ret = self._retry_gql(
  File "/Users/weichaozhou/.pyenv/versions/3.10.6/lib/python3.10/site-packages/wandb/sdk/lib/retry.py", line 147, in __call__
    retry_timedelta_triggered = check_retry_fn(e)
  File "/Users/weichaozhou/.pyenv/versions/3.10.6/lib/python3.10/site-packages/wandb/util.py", line 968, in check_retry_fn
    return fallback_retry_fn(e)
  File "/Users/weichaozhou/.pyenv/versions/3.10.6/lib/python3.10/site-packages/wandb/util.py", line 910, in no_retry_auth
    raise CommError(
wandb.errors.CommError: It appears that you do not have permission to access the requested resource. Please reach out to the project owner to grant you access. If you have the correct permissions, verify that there are no issues with your networking setup.(Error 404: Not Found)
2024-07-15 01:52:48,387 DEBUG   HandlerThread:63702 [handler.py:handle_request():158] handle_request: shutdown
2024-07-15 01:52:48,387 INFO    HandlerThread:63702 [handler.py:finish():882] shutting down handler
2024-07-15 01:52:49,026 INFO    WriterThread:63702 [datastore.py:close():296] close: /Users/weichaozhou/Workspace/MIT-REALM/ada_cbf/f1tenth_gym/examples/wandb/run-20240715_015247-xo787mlp/run-xo787mlp.wandb
2024-07-15 01:52:49,243 INFO    SenderThread:63702 [sender.py:finish():1608] shutting down sender
